Traceback (most recent call last):
  File "F:\OneDrive - str.ucture GmbH\General\CoKLIMAx (Phase 2)\CoKLIMAx-II\myenv\lib\site-packages\jupyter_cache\executors\utils.py", line 58, in single_nb_execution
    executenb(
  File "F:\OneDrive - str.ucture GmbH\General\CoKLIMAx (Phase 2)\CoKLIMAx-II\myenv\lib\site-packages\nbclient\client.py", line 1314, in execute
    return NotebookClient(nb=nb, resources=resources, km=km, **kwargs).execute()
  File "F:\OneDrive - str.ucture GmbH\General\CoKLIMAx (Phase 2)\CoKLIMAx-II\myenv\lib\site-packages\jupyter_core\utils\__init__.py", line 165, in wrapped
    return loop.run_until_complete(inner)
  File "C:\Users\Shailesh\AppData\Local\Programs\Python\Python310\lib\asyncio\base_events.py", line 641, in run_until_complete
    return future.result()
  File "F:\OneDrive - str.ucture GmbH\General\CoKLIMAx (Phase 2)\CoKLIMAx-II\myenv\lib\site-packages\nbclient\client.py", line 709, in async_execute
    await self.async_execute_cell(
  File "F:\OneDrive - str.ucture GmbH\General\CoKLIMAx (Phase 2)\CoKLIMAx-II\myenv\lib\site-packages\nbclient\client.py", line 1062, in async_execute_cell
    await self._check_raise_for_error(cell, cell_index, exec_reply)
  File "F:\OneDrive - str.ucture GmbH\General\CoKLIMAx (Phase 2)\CoKLIMAx-II\myenv\lib\site-packages\nbclient\client.py", line 918, in _check_raise_for_error
    raise CellExecutionError.from_cell_and_msg(cell, exec_reply_content)
nbclient.exceptions.CellExecutionError: An error occurred while executing the following cell:
------------------
import zipfile

# Erstellen Sie den Dateinamen und den Dateipfad fÃ¼r die ZIP-Datei des Datensatzes
dataset_filename = f"{dataset}_heat_wave_days.zip"
dataset_filepath = os.path.join(download_folder, dataset_filename)

# Ã–ffnen Sie die Zip-Datei im Lesemodus und extrahieren Sie den Inhalt in den Arbeitsordner
with zipfile.ZipFile(dataset_filepath, 'r') as zip_ref:
    zip_ref.extractall(working_folder)
    
print(f"ZIP-Datei wurde in das Verzeichnis {working_folder} entpackt")
------------------


[1;31m---------------------------------------------------------------------------[0m
[1;31mPermissionError[0m                           Traceback (most recent call last)
Cell [1;32mIn[5], line 9[0m
[0;32m      7[0m [38;5;66;03m# Ã–ffnen Sie die Zip-Datei im Lesemodus und extrahieren Sie den Inhalt in den Arbeitsordner[39;00m
[0;32m      8[0m [38;5;28;01mwith[39;00m zipfile[38;5;241m.[39mZipFile(dataset_filepath, [38;5;124m'[39m[38;5;124mr[39m[38;5;124m'[39m) [38;5;28;01mas[39;00m zip_ref:
[1;32m----> 9[0m     [43mzip_ref[49m[38;5;241;43m.[39;49m[43mextractall[49m[43m([49m[43mworking_folder[49m[43m)[49m
[0;32m     11[0m [38;5;28mprint[39m([38;5;124mf[39m[38;5;124m"[39m[38;5;124mZIP-Datei wurde in das Verzeichnis [39m[38;5;132;01m{[39;00mworking_folder[38;5;132;01m}[39;00m[38;5;124m entpackt[39m[38;5;124m"[39m)

File [1;32m~\AppData\Local\Programs\Python\Python310\lib\zipfile.py:1634[0m, in [0;36mZipFile.extractall[1;34m(self, path, members, pwd)[0m
[0;32m   1631[0m     path [38;5;241m=[39m os[38;5;241m.[39mfspath(path)
[0;32m   1633[0m [38;5;28;01mfor[39;00m zipinfo [38;5;129;01min[39;00m members:
[1;32m-> 1634[0m     [38;5;28;43mself[39;49m[38;5;241;43m.[39;49m[43m_extract_member[49m[43m([49m[43mzipinfo[49m[43m,[49m[43m [49m[43mpath[49m[43m,[49m[43m [49m[43mpwd[49m[43m)[49m

File [1;32m~\AppData\Local\Programs\Python\Python310\lib\zipfile.py:1689[0m, in [0;36mZipFile._extract_member[1;34m(self, member, targetpath, pwd)[0m
[0;32m   1685[0m     [38;5;28;01mreturn[39;00m targetpath
[0;32m   1687[0m [38;5;28;01mwith[39;00m [38;5;28mself[39m[38;5;241m.[39mopen(member, pwd[38;5;241m=[39mpwd) [38;5;28;01mas[39;00m source, \
[0;32m   1688[0m      [38;5;28mopen[39m(targetpath, [38;5;124m"[39m[38;5;124mwb[39m[38;5;124m"[39m) [38;5;28;01mas[39;00m target:
[1;32m-> 1689[0m     [43mshutil[49m[38;5;241;43m.[39;49m[43mcopyfileobj[49m[43m([49m[43msource[49m[43m,[49m[43m [49m[43mtarget[49m[43m)[49m
[0;32m   1691[0m [38;5;28;01mreturn[39;00m targetpath

File [1;32m~\AppData\Local\Programs\Python\Python310\lib\shutil.py:198[0m, in [0;36mcopyfileobj[1;34m(fsrc, fdst, length)[0m
[0;32m    196[0m [38;5;28;01mif[39;00m [38;5;129;01mnot[39;00m buf:
[0;32m    197[0m     [38;5;28;01mbreak[39;00m
[1;32m--> 198[0m [43mfdst_write[49m[43m([49m[43mbuf[49m[43m)[49m

[1;31mPermissionError[0m: [Errno 13] Permission denied

