Traceback (most recent call last):
  File "c:\Users\ShaileshShrestha\anaconda3\envs\cds_env\lib\site-packages\jupyter_cache\executors\utils.py", line 58, in single_nb_execution
    executenb(
  File "c:\Users\ShaileshShrestha\anaconda3\envs\cds_env\lib\site-packages\nbclient\client.py", line 1319, in execute
    return NotebookClient(nb=nb, resources=resources, km=km, **kwargs).execute()
  File "c:\Users\ShaileshShrestha\anaconda3\envs\cds_env\lib\site-packages\jupyter_core\utils\__init__.py", line 165, in wrapped
    return loop.run_until_complete(inner)
  File "c:\Users\ShaileshShrestha\anaconda3\envs\cds_env\lib\asyncio\base_events.py", line 649, in run_until_complete
    return future.result()
  File "c:\Users\ShaileshShrestha\anaconda3\envs\cds_env\lib\site-packages\nbclient\client.py", line 709, in async_execute
    await self.async_execute_cell(
  File "c:\Users\ShaileshShrestha\anaconda3\envs\cds_env\lib\site-packages\nbclient\client.py", line 1062, in async_execute_cell
    await self._check_raise_for_error(cell, cell_index, exec_reply)
  File "c:\Users\ShaileshShrestha\anaconda3\envs\cds_env\lib\site-packages\nbclient\client.py", line 918, in _check_raise_for_error
    raise CellExecutionError.from_cell_and_msg(cell, exec_reply_content)
nbclient.exceptions.CellExecutionError: An error occurred while executing the following cell:
------------------
# Authenticate with the USGS API
api = API(username=username, password=password)

# Search for available scenes
scenes = api.search(
    dataset='landsat_ot_c2_l2',
    latitude=47.6780,
    longitude=9.1737,
    start_date='2020-01-01',
    end_date='2020-10-01',
    max_cloud_cover=10
)

# Output the number of scenes found
print(f"{len(scenes)} scenes found.")
------------------


[1;31m---------------------------------------------------------------------------[0m
[1;31mUSGSError[0m                                 Traceback (most recent call last)
Cell [1;32mIn[4], line 2[0m
[0;32m      1[0m [38;5;66;03m# Authenticate with the USGS API[39;00m
[1;32m----> 2[0m api [38;5;241m=[39m [43mAPI[49m[43m([49m[43musername[49m[38;5;241;43m=[39;49m[43musername[49m[43m,[49m[43m [49m[43mpassword[49m[38;5;241;43m=[39;49m[43mpassword[49m[43m)[49m
[0;32m      4[0m [38;5;66;03m# Search for available scenes[39;00m
[0;32m      5[0m scenes [38;5;241m=[39m api[38;5;241m.[39msearch(
[0;32m      6[0m     dataset[38;5;241m=[39m[38;5;124m'[39m[38;5;124mlandsat_ot_c2_l2[39m[38;5;124m'[39m,
[0;32m      7[0m     latitude[38;5;241m=[39m[38;5;241m47.6780[39m,
[1;32m   (...)[0m
[0;32m     11[0m     max_cloud_cover[38;5;241m=[39m[38;5;241m10[39m
[0;32m     12[0m )

File [1;32mc:\Users\ShaileshShrestha\anaconda3\envs\cds_env\lib\site-packages\landsatxplore\api.py:39[0m, in [0;36mAPI.__init__[1;34m(self, username, password)[0m
[0;32m     37[0m [38;5;28mself[39m[38;5;241m.[39murl [38;5;241m=[39m API_URL
[0;32m     38[0m [38;5;28mself[39m[38;5;241m.[39msession [38;5;241m=[39m requests[38;5;241m.[39mSession()
[1;32m---> 39[0m [38;5;28;43mself[39;49m[38;5;241;43m.[39;49m[43mlogin[49m[43m([49m[43musername[49m[43m,[49m[43m [49m[43mpassword[49m[43m)[49m

File [1;32mc:\Users\ShaileshShrestha\anaconda3\envs\cds_env\lib\site-packages\landsatxplore\api.py:107[0m, in [0;36mAPI.login[1;34m(self, username, password)[0m
[0;32m    105[0m payload [38;5;241m=[39m {[38;5;124m"[39m[38;5;124musername[39m[38;5;124m"[39m: username, [38;5;124m"[39m[38;5;124mpassword[39m[38;5;124m"[39m: password}
[0;32m    106[0m r [38;5;241m=[39m [38;5;28mself[39m[38;5;241m.[39msession[38;5;241m.[39mpost(login_url, json[38;5;241m.[39mdumps(payload))
[1;32m--> 107[0m [38;5;28;43mself[39;49m[38;5;241;43m.[39;49m[43mraise_api_error[49m[43m([49m[43mr[49m[43m)[49m
[0;32m    108[0m [38;5;28mself[39m[38;5;241m.[39msession[38;5;241m.[39mheaders[[38;5;124m"[39m[38;5;124mX-Auth-Token[39m[38;5;124m"[39m] [38;5;241m=[39m r[38;5;241m.[39mjson()[38;5;241m.[39mget([38;5;124m"[39m[38;5;124mdata[39m[38;5;124m"[39m)

File [1;32mc:\Users\ShaileshShrestha\anaconda3\envs\cds_env\lib\site-packages\landsatxplore\api.py:59[0m, in [0;36mAPI.raise_api_error[1;34m(response)[0m
[0;32m     57[0m     [38;5;28;01mraise[39;00m USGSRateLimitError([38;5;124mf[39m[38;5;124m"[39m[38;5;132;01m{[39;00merror_code[38;5;132;01m}[39;00m[38;5;124m: [39m[38;5;132;01m{[39;00merror_msg[38;5;132;01m}[39;00m[38;5;124m.[39m[38;5;124m"[39m)
[0;32m     58[0m [38;5;28;01melse[39;00m:
[1;32m---> 59[0m     [38;5;28;01mraise[39;00m USGSError([38;5;124mf[39m[38;5;124m"[39m[38;5;132;01m{[39;00merror_code[38;5;132;01m}[39;00m[38;5;124m: [39m[38;5;132;01m{[39;00merror_msg[38;5;132;01m}[39;00m[38;5;124m.[39m[38;5;124m"[39m)

[1;31mUSGSError[0m: NOT_FOUND: Invalid Endpoint.

