Traceback (most recent call last):
  File "C:\Users\ShaileshShrestha\anaconda3\envs\cds_env\lib\site-packages\jupyter_cache\executors\utils.py", line 58, in single_nb_execution
    executenb(
  File "C:\Users\ShaileshShrestha\anaconda3\envs\cds_env\lib\site-packages\nbclient\client.py", line 1319, in execute
    return NotebookClient(nb=nb, resources=resources, km=km, **kwargs).execute()
  File "C:\Users\ShaileshShrestha\anaconda3\envs\cds_env\lib\site-packages\jupyter_core\utils\__init__.py", line 165, in wrapped
    return loop.run_until_complete(inner)
  File "C:\Users\ShaileshShrestha\anaconda3\envs\cds_env\lib\asyncio\base_events.py", line 649, in run_until_complete
    return future.result()
  File "C:\Users\ShaileshShrestha\anaconda3\envs\cds_env\lib\site-packages\nbclient\client.py", line 709, in async_execute
    await self.async_execute_cell(
  File "C:\Users\ShaileshShrestha\anaconda3\envs\cds_env\lib\site-packages\nbclient\client.py", line 1062, in async_execute_cell
    await self._check_raise_for_error(cell, cell_index, exec_reply)
  File "C:\Users\ShaileshShrestha\anaconda3\envs\cds_env\lib\site-packages\nbclient\client.py", line 918, in _check_raise_for_error
    raise CellExecutionError.from_cell_and_msg(cell, exec_reply_content)
nbclient.exceptions.CellExecutionError: An error occurred while executing the following cell:
------------------
# Modify the selected period here
selected_definition = definition_list[0] # 0: climatological_related, 1: health_related, 2: country_related
print(selected_definition)

extract_folder = os.path.join(working_folder, selected_definition)
------------------


[1;31m---------------------------------------------------------------------------[0m
[1;31mNameError[0m                                 Traceback (most recent call last)
Cell [1;32mIn[8], line 2[0m
[0;32m      1[0m [38;5;66;03m# Modify the selected period here[39;00m
[1;32m----> 2[0m selected_definition [38;5;241m=[39m [43mdefinition_list[49m[[38;5;241m0[39m] [38;5;66;03m# 0: climatological_related, 1: health_related, 2: country_related[39;00m
[0;32m      3[0m [38;5;28mprint[39m(selected_definition)
[0;32m      5[0m extract_folder [38;5;241m=[39m os[38;5;241m.[39mpath[38;5;241m.[39mjoin(working_folder, selected_definition)

[1;31mNameError[0m: name 'definition_list' is not defined

