Traceback (most recent call last):
  File "C:\Users\ShaileshShrestha\anaconda3\envs\myenv\lib\site-packages\jupyter_cache\executors\utils.py", line 58, in single_nb_execution
    executenb(
  File "C:\Users\ShaileshShrestha\anaconda3\envs\myenv\lib\site-packages\nbclient\client.py", line 1319, in execute
    return NotebookClient(nb=nb, resources=resources, km=km, **kwargs).execute()
  File "C:\Users\ShaileshShrestha\anaconda3\envs\myenv\lib\site-packages\jupyter_core\utils\__init__.py", line 165, in wrapped
    return loop.run_until_complete(inner)
  File "C:\Users\ShaileshShrestha\anaconda3\envs\myenv\lib\asyncio\base_events.py", line 649, in run_until_complete
    return future.result()
  File "C:\Users\ShaileshShrestha\anaconda3\envs\myenv\lib\site-packages\nbclient\client.py", line 709, in async_execute
    await self.async_execute_cell(
  File "C:\Users\ShaileshShrestha\anaconda3\envs\myenv\lib\site-packages\nbclient\client.py", line 1062, in async_execute_cell
    await self._check_raise_for_error(cell, cell_index, exec_reply)
  File "C:\Users\ShaileshShrestha\anaconda3\envs\myenv\lib\site-packages\nbclient\client.py", line 918, in _check_raise_for_error
    raise CellExecutionError.from_cell_and_msg(cell, exec_reply_content)
nbclient.exceptions.CellExecutionError: An error occurred while executing the following cell:
------------------
import json
from landsatxplore.api import API

# Load credentials from the local JSON file
with open(r"D:/usgs.json", "r") as file:
    credentials = json.load(file)

username = credentials["username"]
password = credentials["password"]
------------------


[1;31m---------------------------------------------------------------------------[0m
[1;31mFileNotFoundError[0m                         Traceback (most recent call last)
Cell [1;32mIn[2], line 5[0m
[0;32m      2[0m [38;5;28;01mfrom[39;00m[38;5;250m [39m[38;5;21;01mlandsatxplore[39;00m[38;5;21;01m.[39;00m[38;5;21;01mapi[39;00m[38;5;250m [39m[38;5;28;01mimport[39;00m API
[0;32m      4[0m [38;5;66;03m# Load credentials from the local JSON file[39;00m
[1;32m----> 5[0m [38;5;28;01mwith[39;00m [38;5;28;43mopen[39;49m[43m([49m[38;5;124;43mr[39;49m[38;5;124;43m"[39;49m[38;5;124;43mD:/usgs.json[39;49m[38;5;124;43m"[39;49m[43m,[49m[43m [49m[38;5;124;43m"[39;49m[38;5;124;43mr[39;49m[38;5;124;43m"[39;49m[43m)[49m [38;5;28;01mas[39;00m file:
[0;32m      6[0m     credentials [38;5;241m=[39m json[38;5;241m.[39mload(file)
[0;32m      8[0m username [38;5;241m=[39m credentials[[38;5;124m"[39m[38;5;124musername[39m[38;5;124m"[39m]

File [1;32m~\anaconda3\envs\myenv\lib\site-packages\IPython\core\interactiveshell.py:324[0m, in [0;36m_modified_open[1;34m(file, *args, **kwargs)[0m
[0;32m    317[0m [38;5;28;01mif[39;00m file [38;5;129;01min[39;00m {[38;5;241m0[39m, [38;5;241m1[39m, [38;5;241m2[39m}:
[0;32m    318[0m     [38;5;28;01mraise[39;00m [38;5;167;01mValueError[39;00m(
[0;32m    319[0m         [38;5;124mf[39m[38;5;124m"[39m[38;5;124mIPython won[39m[38;5;124m'[39m[38;5;124mt let you open fd=[39m[38;5;132;01m{[39;00mfile[38;5;132;01m}[39;00m[38;5;124m by default [39m[38;5;124m"[39m
[0;32m    320[0m         [38;5;124m"[39m[38;5;124mas it is likely to crash IPython. If you know what you are doing, [39m[38;5;124m"[39m
[0;32m    321[0m         [38;5;124m"[39m[38;5;124myou can use builtins[39m[38;5;124m'[39m[38;5;124m open.[39m[38;5;124m"[39m
[0;32m    322[0m     )
[1;32m--> 324[0m [38;5;28;01mreturn[39;00m io_open(file, [38;5;241m*[39margs, [38;5;241m*[39m[38;5;241m*[39mkwargs)

[1;31mFileNotFoundError[0m: [Errno 2] No such file or directory: 'D:/usgs.json'

